Workbook

Sheet Audit Mandiri_IAU BANPT
I1: Form 2
B2: EVALUASI PROGRAM STUDI SARJANA
B3: KONFIRMASI TINDAKAN PERBAIKAN TEMUAN AMAI SIKLUS 3 - 2024
B4: Program Studi
G5: Sastra Inggris
B7: YANG DI ISI HANYA SEL YANG BERWARNA KUNING
B8: Program Studi
B9: Bagian 1. VMTS
B10: NO. | C10: BAGIAN | H10: NILAI | I10: DESKRIPSI HASIL ASESMEN
B11: 1. | C11: Pemenuhan Unsur VMTS
B12: A. | C12: Apakah UPPS merumuskan visi keilmuan program studi dan tujuan program studi sesuai kriteria berikut: 1. selaras dengan defernsiasi misi dan visi UPPS maupun Perguruan Tinggi; 2. didukung dengan keberadaan standar luaran, standar proses dan standar masukan tridharma yang relevan dan mengarah pada pencapaian tujuan program studi; 3. dievaluasi pencapaiannya untuk perbaikan berkelanjutan
C13: 4 | F13: (a) Visi keilmuan dan tujuan program studi yang diakreditasi telah dirumuskan dengan jelas dan selaras dengan deferensiasi misi dan visi UPPS maupun Perguruan Tinggi. (b) Program studi memiliki rujukan standar luaran, standar proses dan standar masukan yang memberikan arah yang jelas dalam pencapaian visi keilmuan dan tujuan program studi. (c) Tujuan program studi yang diakreditasi dievaluasi secara reguler dan hasilnya digunakan untuk perbaikan mutu berkelanjutan
C14: 3 | F14: Program studi tidak memenuhi satu atau lebih hal-hal berikut: (a) Visi keilmuan dan tujuan program studi yang diakreditasi telah dirumuskan dengan jelas dan selaras dengan deferensiasi misi dan visi UPPS maupun Perguruan Tinggi. (b) Program studi memiliki rujukan standar luaran, standar proses dan standar masukan yang memberikan arah yang jelas dalam pencapaian visi keilmuan dan tujuan program studi. (c) Tujuan program studi yang diakreditasi dievaluasi secara reguler dan hasil evaluasi digunakan untuk perbaikan mutu berkelanjutan.
C15: 0 | F15: UPPS memiliki misi, tujuan, dan strategi yang tidak terkait dengan strategi perguruan tinggi dan pengembangan program studi
B16: B. | C16: Apakah strategi disusun secara partisipatif dan berbasis evaluasi
C17: 4 | F17: Strategi disusun berdasarkan analisis yang sistematis dengan menggunakan metoda yang relevan, melibatkan pemangku kepentingan internal dan eksternal, dan terdokumentasi serta pada pelaksanaannya dilakukan pemantauan dan evaluasi dan ditindaklanjuti
C18: 3 | F18: Strategi disusun berdasarkan analisis yang sistematis dengan menggunakan metoda yang relevan, melibatkan pemangku kepentingan internal, dan terdokumentasi serta pada pelaksanaannya dilakukan pemantauan dan evaluasi
C19: 0 | F19: Tidak memiliki mekanisme penyusunan strategi
B21: Bagian 2. TATA PAMONG DAN KERJA SAMA
B22: NO. | C22: BAGIAN | H22: NILAI | I22: DESKRIPSI HASIL EVALUASI DIRI
B23: 2 | C23: Pemenuhan Unsur Tata Pamong dan Kerja Sama
B24: A. | C24: Apakah UPPS/Prodi memiliki kelengkapan struktur organisasi dan keefektifan penyelenggaraan organisasi.
C25: 4 | F25: UPPS memiliki dokumen formal struktur organisasi dan tata kerja yang dilengkapi tugas dan fungsinya, serta telah berjalan secara konsisten dan menjamin tata pamong yang baik serta berjalan efektif dan efisien
C26: 3 | F26: UPPS memiliki dokumen formal struktur organisasi dan tata kerja yang dilengkapi tugas dan fungsinya, serta telah berjalan secara konsisten dan menjamin tata pamong yang baik
C27: 0 | F27: -
B28: B. | C28: Apakah mutu, manfaat, kepuasan dan keberlanjutan kerjasama pendidikan, penelitian dan PkM yang relevan dengan program studi yang berjalan telah memenuhi 3 aspek berikut: 1. memberikan manfaat bagi program studi dalam pemenuhan proses pembelajaran, penelitian, PkM 2. memberikan peningkatan kinerja tridharma dan fasilitas pendukung program studi 3. memberikan kepuasan kepada mitra industri dan mitra kerja sama lainnya, serta menjamin keberlanjutan kerja sama dan hasilnya
C29: 4 | F29: UPPS memiliki bukti yang sahih terkait kerjasama yang ada telah memenuhi 3 aspek.
C30: 3 | F30: UPPS memiliki bukti yang sahih terkait kerjasama yang ada telah memenuhi 1-2 aspek.
C31: 0 | F31: -
B32: C. | C32: Apakah UPPS/Prodi memiliki/menetapkan indikator kinerja tambahan yang menunjukkan daya saing UPPS dan program studi di tingkat inernasional
C33: 4 | F33: UPPS menetapkan indikator kinerja tambahan berdasarkan standar pendidikan tinggi yang ditetapkan perguruan tinggi. Indikator kinerja tambahan mencakup seluruh kriteria serta menunjukkan daya saing UPPS dan program studi di tingkat inernasional. Data indikator kinerja tambahan telah diukur, dimonitor, dikaji, dan dianalisis untuk perbaikan berkelanjutan.
C34: 3 | F34: UPPS menetapkan indikator kinerja tambahan berdasarkan standar pendidikan tinggi yang ditetapkan perguruan tinggi. Indikator kinerja tambahan mencakup seluruh kriteria serta menunjukkan daya saing UPPS dan program studi di tingkat inernasional. Data indikator kinerja tambahan telah diukur, dimonitor, dikaji.
C35: 0 | F35: -
B37: Bagian 3. Prestasi Mahasiswa
B38: NO. | C38: BAGIAN | H38: NILAI | I38: DESKRIPSI HASIL EVALUASI DIRI
B39: 3 | C39: Pemenuhan Unsur Prestasi Mahasiswa
B40: A. | C40: Berapa skor prestasi akademik mahasiswa dalam 3 tahun terakhir | H40: =2 + (20*H45 + 100*H46) - (1000*H46*H45) -> 4.0498615
C41: NI = Jumlah prestasi akademik internasional | H41: 5
C42: NN = Jumlah prestasi akademik nasional | H42: 2
C43: NW = Jumlah prestasi akademik wilayah/lokal | H43: 2
...

Sheet Form 3
I1: Form 3
C2: Berita Acara Audit Mutu Internal
H3: Periode Audit:
H4: TA 2025/2026
C5: Teraudit: | D5: Program Studi | F5: ='Audit Mandiri_IAU BANPT'!G8 -> 0 | H5: Tanggal Audit
C6: Ruang Lingkup: | E6: Akademik/Non Akademik
A8: Hasil Konfirmasi Auditee
A9: Penyelesaian Permintaan Tindakan Koreksi (PTK) AMI siklus sebelumnya
A10: No | B10: Pernyataan Standar | E10: Konfirmasi Auditee | G10: Skor | H10: Status Akhir
A12: 1 | B12: ='Audit Mandiri_IAU BANPT'!C12 -> Apakah UPPS merumuskan visi keilmuan program studi dan tujuan program studi sesuai kriteria berikut: 1. selaras dengan defernsiasi misi dan visi UPPS maupun Perguruan Tinggi; 2. didukung dengan keberadaan standar luaran, standar proses dan standar masukan tridharma yang relevan dan mengarah pada pencapaian tujuan program studi; 3. dievaluasi pencapaiannya untuk perbaikan berkelanjutan | E12: ='Audit Mandiri_IAU BANPT'!I12 -> 0 | G12: ='Audit Mandiri_IAU BANPT'!H12 -> 0 | H12: =IF(G12=4,"Mencapai",IF(G12=3,"Belum Mencapai","Tidak Mencapai")) -> Tidak Mencapai
A13: 2 | B13: ='Audit Mandiri_IAU BANPT'!C16 -> Apakah strategi disusun secara partisipatif dan berbasis evaluasi | E13: ='Audit Mandiri_IAU BANPT'!I16 -> 0 | G13: ='Audit Mandiri_IAU BANPT'!H16 -> 0 | H13: =IF(G13=4,"Mencapai",IF(G13=3,"Belum Mencapai","Tidak Mencapai")) -> Tidak Mencapai
A14: 3 | B14: ='Audit Mandiri_IAU BANPT'!C24 -> Apakah UPPS/Prodi memiliki kelengkapan struktur organisasi dan keefektifan penyelenggaraan organisasi. | E14: ='Audit Mandiri_IAU BANPT'!I24 -> 0 | G14: ='Audit Mandiri_IAU BANPT'!H24 -> 0 | H14: =IF(G14=4,"Mencapai",IF(G14=3,"Belum Mencapai","Tidak Mencapai")) -> Tidak Mencapai
A15: 4 | B15: ='Audit Mandiri_IAU BANPT'!C28 -> Apakah mutu, manfaat, kepuasan dan keberlanjutan kerjasama pendidikan, penelitian dan PkM yang relevan dengan program studi yang berjalan telah memenuhi 3 aspek berikut: 1. memberikan manfaat bagi program studi dalam pemenuhan proses pembelajaran, penelitian, PkM 2. memberikan peningkatan kinerja tridharma dan fasilitas pendukung program studi 3. memberikan kepuasan kepada mitra industri dan mitra kerja sama lainnya, serta menjamin keberlanjutan kerja sama dan hasilnya | E15: ='Audit Mandiri_IAU BANPT'!I28 -> 0 | G15: ='Audit Mandiri_IAU BANPT'!H28 -> 0 | H15: =IF(G15=4,"Mencapai",IF(G15=3,"Belum Mencapai","Tidak Mencapai")) -> Tidak Mencapai
A16: 5 | B16: ='Audit Mandiri_IAU BANPT'!C32 -> Apakah UPPS/Prodi memiliki/menetapkan indikator kinerja tambahan yang menunjukkan daya saing UPPS dan program studi di tingkat inernasional | E16: ='Audit Mandiri_IAU BANPT'!I32 -> 0 | G16: ='Audit Mandiri_IAU BANPT'!H32 -> 0 | H16: =IF(G16=4,"Mencapai",IF(G16=3,"Belum Mencapai","Tidak Mencapai")) -> Tidak Mencapai
A17: 6 | B17: ='Audit Mandiri_IAU BANPT'!C40 -> Berapa skor prestasi akademik mahasiswa dalam 3 tahun terakhir | E17: ='Audit Mandiri_IAU BANPT'!I40 -> 0 | G17: ='Audit Mandiri_IAU BANPT'!H40 -> 4.0498615 | H17: =IF(G17=4,"Mencapai",IF(G17=3,"Belum Mencapai","Tidak Mencapai")) -> Tidak Mencapai
A18: 7 | B18: ='Audit Mandiri_IAU BANPT'!C51 -> Berapa persentase dan skor kualifikasi akademik Dosen Tetap Penghitung Rasio (DTPR) (S3 > 25%) | E18: ='Audit Mandiri_IAU BANPT'!I51 -> 0 | G18: ='Audit Mandiri_IAU BANPT'!H51 -> 4 | H18: =IF(G18=4,"Mencapai",IF(G18=3,"Belum Mencapai","Tidak Mencapai")) -> Mencapai
A19: 8 | B19: ='Audit Mandiri_IAU BANPT'!C55 -> Berapa persentase dan skor DTPR yang memiliki jabatan akademik GB, LK, dan L | E19: ='Audit Mandiri_IAU BANPT'!I55 -> 0 | G19: ='Audit Mandiri_IAU BANPT'!H55 -> 4.1428571 | H19: =IF(G19=4,"Mencapai",IF(G19=3,"Belum Mencapai","Tidak Mencapai")) -> Tidak Mencapai
A20: 9 | B20: ='Audit Mandiri_IAU BANPT'!C61 -> Berapa persentase dan skor DTPS yang memiliki pengakuan/rekognisi atas kepakaran/prestasi/kinerja; Visiting lecturer di PT Internasional/A, keynote speaker internasional/nasional, mitra bestari jurnal internasional bereputasi/nasional, staf ahli lembaga internasional/nasional sesuai bidang ilmu, penghargaan atas prestasi dan kinerja tingkat wilayah/nasional/internasional (NRD) 3 tahun terakhir | E20: ='Audit Mandiri_IAU BANPT'!I61 -> 0 | G20: ='Audit Mandiri_IAU BANPT'!H61 -> 5 | H20: =IF(G20=4,"Mencapai",IF(G20=3,"Belum Mencapai","Tidak Mencapai")) -> Tidak Mencapai
A21: 10 | B21: ='Audit Mandiri_IAU BANPT'!C69 -> Apakah UPPS/Prodi memiliki kecukupan dana untuk menjamin pencapaian capaian pembelajaran. | E21: ='Audit Mandiri_IAU BANPT'!I69 -> 0 | G21: ='Audit Mandiri_IAU BANPT'!H69 -> 0 | H21: =IF(G21=4,"Mencapai",IF(G21=3,"Belum Mencapai","Tidak Mencapai")) -> Tidak Mencapai
A22: 11 | B22: ='Audit Mandiri_IAU BANPT'!C73 -> Apakah UPPS/Prodi memiliki kecukupan, aksesibilitas dan mutu sarana dan prasarana untuk menjamin pencapaian capaian pembelajaran dan meningkatkan suasana akademik | E22: ='Audit Mandiri_IAU BANPT'!I73 -> 0 | G22: ='Audit Mandiri_IAU BANPT'!H73 -> 0 | H22: =IF(G22=4,"Mencapai",IF(G22=3,"Belum Mencapai","Tidak Mencapai")) -> Tidak Mencapai
A23: 12 | B23: ='Audit Mandiri_IAU BANPT'!C81 -> Pengukuran terhadap CPL | E23: ='Audit Mandiri_IAU BANPT'!I81 -> 0 | G23: ='Audit Mandiri_IAU BANPT'!H81 -> 0 | H23: =IF(G23=4,"Mencapai",IF(G23=3,"Belum Mencapai","Tidak Mencapai")) -> Tidak Mencapai
A24: 13 | B24: ='Audit Mandiri_IAU BANPT'!C85 -> Program Studi memiliki lulusan yang memenuhi CPL | E24: ='Audit Mandiri_IAU BANPT'!I85 -> 0 | G24: ='Audit Mandiri_IAU BANPT'!H85 -> 0 | H24: =IF(G24=4,"Mencapai",IF(G24=3,"Belum Mencapai","Tidak Mencapai")) -> Tidak Mencapai
A25: 14 | B25: ='Audit Mandiri_IAU BANPT'!C93 -> Apakah terdapat peningkatan kegiatan penelitian dalam 3 tahun terakhir | E25: ='Audit Mandiri_IAU BANPT'!I93 -> 0 | G25: ='Audit Mandiri_IAU BANPT'!H93 -> 0 | H25: =IF(G25=4,"Mencapai",IF(G25=3,"Belum Mencapai","Tidak Mencapai")) -> Tidak Mencapai
A26: 15 | B26: ='Audit Mandiri_IAU BANPT'!C97 -> Apakah terdapat peningkatan kegiatan penelitian dalam 3 tahun terakhir melibatkan mahasiswa | E26: ='Audit Mandiri_IAU BANPT'!I97 -> 0 | G26: ='Audit Mandiri_IAU BANPT'!H97 -> 0 | H26: =IF(G26=4,"Mencapai",IF(G26=3,"Belum Mencapai","Tidak Mencapai")) -> Tidak Mencapai
A27: 16 | B27: ='Audit Mandiri_IAU BANPT'!C101 -> Apakah terdapat peningkatan kegiatan PkM dalam 3 tahun terakhir | E27: ='Audit Mandiri_IAU BANPT'!I101 -> 0 | G27: ='Audit Mandiri_IAU BANPT'!H101 -> 0 | H27: =IF(G27=4,"Mencapai",IF(G27=3,"Belum Mencapai","Tidak Mencapai")) -> Tidak Mencapai
A28: 17 | B28: ='Audit Mandiri_IAU BANPT'!C105 -> Apakah terdapat peningkatan kegiatan PkM dalam 3 tahun terakhir melibatkan mahasiswa | E28: ='Audit Mandiri_IAU BANPT'!I105 -> 0 | G28: ='Audit Mandiri_IAU BANPT'!H105 -> 0 | H28: =IF(G28=4,"Mencapai",IF(G28=3,"Belum Mencapai","Tidak Mencapai")) -> Tidak Mencapai
A29: 18 | B29: ='Audit Mandiri_IAU BANPT'!C113 -> Berapakah rata-rata IPK lulusan dalam 3 tahun terakhir | E29: ='Audit Mandiri_IAU BANPT'!I113 -> 0 | G29: ='Audit Mandiri_IAU BANPT'!H113 -> 0 | H29: =IF(G29=4,"Mencapai",IF(G29=3,"Belum Mencapai","Tidak Mencapai")) -> Tidak Mencapai
A30: 19 | B30: ='Audit Mandiri_IAU BANPT'!C117 -> Berapakah rata-rata waktu tunggu lulusan dalam 3 tahun terakhir | E30: ='Audit Mandiri_IAU BANPT'!I117 -> 0 | G30: ='Audit Mandiri_IAU BANPT'!H117 -> 0 | H30: =IF(G30=4,"Mencapai",IF(G30=3,"Belum Mencapai","Tidak Mencapai")) -> Tidak Mencapai
A31: 20 | B31: ='Audit Mandiri_IAU BANPT'!C121 -> Berapakah persentase dan skor luaran penelitian dan PKM yang dihasilkan DTPS dalam 3 tahun terakhir | E31: ='Audit Mandiri_IAU BANPT'!I121 -> 0 | G31: ='Audit Mandiri_IAU BANPT'!H121 -> 8.5 | H31: =IF(G31=4,"Mencapai",IF(G31=3,"Belum Mencapai","Tidak Mencapai")) -> Tidak Mencapai
A33: Siklus AMI | C33: Tgl Berlaku | E33: Status Audit
A34: 4 | E34: Konfirmasi tindak lanjut Prodi atas hasil AMI siklus 4 sesuai format template yang disediakan beserta bukti pendukung
A35: Keterangan
A36: Permintaan Tindakan Koreksi (PTK) 1
A37: Status akhir
A38: Permintaan Tindakan Koreksi (PTK) 2
A39: Status akhir
A40: Permintaan Tindakan Koreksi (PTK) 3
A41: Status akhir
A43: Berdasarkan hasil audit yang telah dilakukan, auditee sepakat melakukan tindak lanjut dan perbaikan terhadap temuan hasil audit internal
C45: Teraudit
...

Sheet Sheet2
B2: Sastra Inggris
B3: DKV
