Workbook

Sheet Audit Mandiri_IAU LAMKES
I1: Form 2
B2: EVALUASI PROGRAM STUDI SARJANA/PROFESI
B3: KONFIRMASI TINDAKAN PERBAIKAN TEMUAN AMAI SIKLUS 3 - 2024
B4: Program Studi
G5: Farmasi
B7: YANG DI ISI HANYA SEL YANG BERWARNA KUNING
B8: Program Studi
B9: Bagian 1. Visi, Misi, Tujuan, Strategi
B10: NO. | C10: BAGIAN | H10: NILAI | I10: DESKRIPSI HASIL EVALUASI DIRI
B11: 1. | C11: Pemenuhan Unsur VMTS
B12: A. | C12: Bagaimana mekanisme penyusunan visi, misi, dan unggulan program studi dan alasannya?
C13: 4 | F13: 1. Prodi memiliki mekanisme untuk mengidentifikasi keterlibatan pemangku kepentingan internal dan eksternal dalam penyusunan visi, misi, dan unggulan; 2. Terdapat kontribusi dari pemangku kepentingan tersebut dan manfaat yang mereka dapatkan 3. Permasalahan kesehatan di tingkat nasional dan lokal dipertimbangkan dalam penyusunan visi, misi, dan unggulan
C14: 3 | F14: 1. Prodi memiliki mekanisme untuk mengidentifikasi keterlibatan pemangku kepentingan internal dan eksternal dalam penyusunan visi, misi, dan unggulan; 2. Terdapat kontribusi dari pemangku kepentingan tersebut dan manfaat yang mereka dapatkan.
C15: 0 | F15: -
B16: B. | C16: Bagaimana peran visi, misi, dan unggulan dalam perencanaan, implementasi, monitoring, penjaminan mutu, dan manajemen di program studi?
C17: 4 | F17: • Visi, misi, dan unggulan diintegrasikan dalam perencanaan program dan kegiatan. • Ada strategi dan implementasi dari perencanaan tersebut. • Struktur organisasi dirancang sesuai dengantata kelola untuk mencapai visi, misi, dan unggulan. • Sistem penjaminan mutu internal dikembangkan sesuai dengan visi, misi, dan unggulan. • Monitoring dan evaluasi dilakukan untuk menilai pencapaian visi, misi, dan unggulan. • Ada tindak lanjut dari hasil monitoring dan evaluasi tersebut. • Visi, misi, dan unggulan dievaluasi dan diperbarui secara berkala.
C18: 3 | F18: • Visi, misi, dan unggulan diintegrasikan dalam perencanaan program dan kegiatan. • Ada strategi dan implementasi dari perencanaan tersebut. • Struktur organisasi dirancang sesuai dengantata kelola untuk mencapai visi, misi, dan unggulan. • Sistem penjaminan mutu internal dikembangkan sesuai dengan visi, misi, dan unggulan. • Monitoring dan evaluasi dilakukan untuk menilai pencapaian visi, misi, dan unggulan. • Tidak Ada tindak lanjut dari hasil monitoring dan evaluasi tersebut.
C19: 0 | F19: -
B20: C. | C20: Bagaimana cara menyosialisasikan visi, misi, dan unggulan program studi, analisis hasil dan tindaklanjutnya?
C21: 4 | F21: • PS menyosialisasikan visi, misi, dan unggulan melalui pemanfaatan berbagai media. • Pihak-pihak yang terlibat dalam kegiatan sosialisasi tersebut. • UPPS dan PS melakukan analisis hasil sosialisasi dan tindaklanjutnya.
C22: 3
C23: 0 | F23: -
B25: Bagian 2. Kurikulum
B26: NO. | C26: BAGIAN | H26: NILAI | I26: DESKRIPSI HASIL EVALUASI DIRI
B27: 2 | C27: Pemenuhan Unsur Kurikulum
B28: A. | C28: Bagaimana cara merancang dan mengembangkan capaian pembelajaran lulusan dan capaian pembelajaran mata kuliah?
C29: 4 | F29: • PS menerapkan visi, misi dan unggulan serta masalah kesehatan utama di masyarakat dalam perumusan capaian pembelajaran lulusan. • PS menerapkan capaian pembelajaran mata kuliah diturunkan secara konsisten dari capaian pembelajaran lulusan. • PS merumuskan capaian pembelajaran mengacu pada peraturan yang berlaku (KKN level 6 (sarjana kefarmasian)) dan peraturan yang berlaku.
C30: 3 | F30: • PS menerapkan visi, misi dan unggulan serta masalah kesehatan utama di masyarakat dalam perumusan capaian pembelajaran lulusan. • PS menerapkan capaian pembelajaran mata kuliah diturunkan secara konsisten dari capaian pembelajaran lulusan.
C31: 0 | F31: -
B32: B. | C32: Bagaimana hubungan antara berbagai disiplin ilmu yang tercakup dalam kurikulum?
C33: 4 | F33: • PS memiliki kriteria untuk identifikasi disiplim ilmu terkait agar isi kurikulum menjadi relevan, penting, dan diprioritaskan. • PS menentukan ruang lingkup, konten, keluasan dan kedalaman cakupan serta konsentrasi. • PS menentukan urutan, yaitu hierarki, dan perkembangan kompleksitas atau tingkat kesulitan. • PS menetapkan struktur kurikulum dengan mengaitkan disiplin ilmu lain yang terkait untuk menunjang disiplin ilmu kefarmasian guna mencapai capaian pembelajaran lulusan.
C34: 3 | F34: • PS memiliki kriteria untuk identifikasi disiplim ilmu terkait agar isi kurikulum menjadi relevan, penting, dan diprioritaskan. • PS menentukan ruang lingkup, konten, keluasan dan kedalaman cakupan serta konsentrasi.
C35: 0
B36: C. | C36: Elemen apa saja dari ilmu biomedis dan sains farmasi yang dimasukkan dalam kurikulum? Bagaimana pilihan pilihan yang dibuat dan waktu yang dialokasikan untuk elemen ini?
C37: 4 | F37: PS mengidentifikasi ilmu biomedis dan sains farmasi yang relevan dengan capaian pembelajaran lulusan dengan memasukkan konten ilmu biomedis dan sains farmasi, beserta alokasi waktu, dan nilai kredit yang sesuai.
C38: 3 | F38: PS mengidentifikasi ilmu biomedis dan sains farmasi yang relevan dengan capaian pembelajaran lulusan dengan memasukkan konten ilmu biomedis dan sains farmasi.
C39: 0 | F39: -
B41: Bagian 3. Penilaian
B42: NO. | C42: BAGIAN | H42: NILAI | I42: DESKRIPSI HASIL EVALUASI DIRI
B43: 3. | C43: Pemenuhan Unsur Penilaian
...

Sheet Sheet1
B2: Farmasi
B3: Apoteker
B5: Optometri

Sheet Form 3 FarApt
I1: Form 3
C2: Berita Acara Audit Mutu Internal
H3: Periode Audit:
H4: TA 2025/2026
C5: Teraudit: | D5: Program Studi | F5: ='Audit Mandiri_IAU LAMKES'!G8 -> 0 | H5: Tanggal Audit
C6: Ruang Lingkup: | E6: Akademik/Non Akademik
A8: Hasil Konfirmasi Auditee
A9: Penyelesaian Permintaan Tindakan Koreksi (PTK) AMI siklus sebelumnya
A10: No | B10: Pernyataan Standar | E10: Konfirmasi Auditee | G10: Skor | H10: Status Akhir
A12: 1 | B12: ='Audit Mandiri_IAU LAMKES'!C12 -> Bagaimana mekanisme penyusunan visi, misi, dan unggulan program studi dan alasannya? | E12: ='Audit Mandiri_IAU LAMKES'!I12 -> 0 | G12: ='Audit Mandiri_IAU LAMKES'!H12 -> 0 | H12: =IF(G12=4,"Mencapai",IF(G12=3,"Belum Mencapai","Tidak Mencapai")) -> Tidak Mencapai
A13: 2 | B13: ='Audit Mandiri_IAU LAMKES'!C16 -> Bagaimana peran visi, misi, dan unggulan dalam perencanaan, implementasi, monitoring, penjaminan mutu, dan manajemen di program studi? | E13: ='Audit Mandiri_IAU LAMKES'!I16 -> 0 | G13: ='Audit Mandiri_IAU LAMKES'!H16 -> 0 | H13: =IF(G13=4,"Mencapai",IF(G13=3,"Belum Mencapai","Tidak Mencapai")) -> Tidak Mencapai
A14: 3 | B14: ='Audit Mandiri_IAU LAMKES'!C20 -> Bagaimana cara menyosialisasikan visi, misi, dan unggulan program studi, analisis hasil dan tindaklanjutnya? | E14: ='Audit Mandiri_IAU LAMKES'!I20 -> 0 | G14: ='Audit Mandiri_IAU LAMKES'!H20 -> 0 | H14: =IF(G14=4,"Mencapai",IF(G14=3,"Belum Mencapai","Tidak Mencapai")) -> Tidak Mencapai
A15: 4 | B15: ='Audit Mandiri_IAU LAMKES'!C28 -> Bagaimana cara merancang dan mengembangkan capaian pembelajaran lulusan dan capaian pembelajaran mata kuliah? | E15: ='Audit Mandiri_IAU LAMKES'!I28 -> 0 | G15: ='Audit Mandiri_IAU LAMKES'!H28 -> 0 | H15: =IF(G15=4,"Mencapai",IF(G15=3,"Belum Mencapai","Tidak Mencapai")) -> Tidak Mencapai
A16: 5 | B16: ='Audit Mandiri_IAU LAMKES'!C32 -> Bagaimana hubungan antara berbagai disiplin ilmu yang tercakup dalam kurikulum? | E16: ='Audit Mandiri_IAU LAMKES'!I32 -> 0 | G16: ='Audit Mandiri_IAU LAMKES'!H32 -> 0 | H16: =IF(G16=4,"Mencapai",IF(G16=3,"Belum Mencapai","Tidak Mencapai")) -> Tidak Mencapai
A17: 6 | B17: ='Audit Mandiri_IAU LAMKES'!C36 -> Elemen apa saja dari ilmu biomedis dan sains farmasi yang dimasukkan dalam kurikulum? Bagaimana pilihan pilihan yang dibuat dan waktu yang dialokasikan untuk elemen ini? | E17: ='Audit Mandiri_IAU LAMKES'!I36 -> 0 | G17: ='Audit Mandiri_IAU LAMKES'!H36 -> 0 | H17: =IF(G17=4,"Mencapai",IF(G17=3,"Belum Mencapai","Tidak Mencapai")) -> Tidak Mencapai
A18: 7 | B18: ='Audit Mandiri_IAU LAMKES'!C44 -> Bagaimana penilaian capaian pembelajaran lulusan yang digunakan oleh PS? | E18: ='Audit Mandiri_IAU LAMKES'!I44 -> 0 | G18: ='Audit Mandiri_IAU LAMKES'!H44 -> 0 | H18: =IF(G18=4,"Mencapai",IF(G18=3,"Belum Mencapai","Tidak Mencapai")) -> Tidak Mencapai
A19: 8 | B19: ='Audit Mandiri_IAU LAMKES'!C48 -> Bagaimana penilaian digunakan sebagai pedoman untuk menentukan perkembangan pembelajaran mahasiswa? | E19: ='Audit Mandiri_IAU LAMKES'!I48 -> 0 | G19: ='Audit Mandiri_IAU LAMKES'!H48 -> 0 | H19: =IF(G19=4,"Mencapai",IF(G19=3,"Belum Mencapai","Tidak Mencapai")) -> Tidak Mencapai
A20: 9 | B20: ='Audit Mandiri_IAU LAMKES'!C52 -> Bagaimana data dari penilaian, digunakan untuk mengevaluasi pembelajaran dan implementasi kurikulum yang digunakan | E20: ='Audit Mandiri_IAU LAMKES'!I52 -> 0 | G20: ='Audit Mandiri_IAU LAMKES'!H52 -> 0 | H20: =IF(G20=4,"Mencapai",IF(G20=3,"Belum Mencapai","Tidak Mencapai")) -> Tidak Mencapai
A21: 10 | B21: ='Audit Mandiri_IAU LAMKES'!C60 -> Bagaimana kebijakan seleksi dan penerimaan Maba dirancang agar bersifat adil dan merata, sesuai dengan kebutuhan lokal? | E21: ='Audit Mandiri_IAU LAMKES'!I60 -> 0 | G21: ='Audit Mandiri_IAU LAMKES'!H60 -> 0 | H21: =IF(G21=4,"Mencapai",IF(G21=3,"Belum Mencapai","Tidak Mencapai")) -> Tidak Mencapai
A22: 11 | B22: ='Audit Mandiri_IAU LAMKES'!C64 -> Bagaimana layanan akademik dan nonakademik direkomendasikan dan dikomunikasikan kepada staf dan mahasiswa? | E22: ='Audit Mandiri_IAU LAMKES'!I64 -> 0 | G22: ='Audit Mandiri_IAU LAMKES'!H64 -> 0 | H22: =IF(G22=4,"Mencapai",IF(G22=3,"Belum Mencapai","Tidak Mencapai")) -> Tidak Mencapai
A23: 12 | B23: ='Audit Mandiri_IAU LAMKES'!C68 -> Bagaimana institusi pendidikan/UPPS memastikan bahwa lingkungan kerja dan belajar mahasiswa memenuhi standar mutu dan keselamatan mahasiswa? | E23: ='Audit Mandiri_IAU LAMKES'!I68 -> 0 | G23: ='Audit Mandiri_IAU LAMKES'!H68 -> 0 | H23: =IF(G23=4,"Mencapai",IF(G23=3,"Belum Mencapai","Tidak Mencapai")) -> Tidak Mencapai
A24: 13 | B24: ='Audit Mandiri_IAU LAMKES'!C76 -> Bagaimana UPPS mengambil tanggung jawab administratif atas penerapan kebijakan pengembangan profesional berkelanjutan dosen? | E24: ='Audit Mandiri_IAU LAMKES'!I76 -> 0 | G24: ='Audit Mandiri_IAU LAMKES'!H76 -> 0 | H24: =IF(G24=4,"Mencapai",IF(G24=3,"Belum Mencapai","Tidak Mencapai")) -> Tidak Mencapai
A25: 14 | B25: ='Audit Mandiri_IAU LAMKES'!C80 -> Bagaimana UPPS dan PS membuat mekanisme untuk menetapkan, mengatur, dan mengevaluasi kinerja dan perilaku dosen? | E25: ='Audit Mandiri_IAU LAMKES'!I80 -> 0 | G25: ='Audit Mandiri_IAU LAMKES'!H80 -> 0 | H25: =IF(G25=4,"Mencapai",IF(G25=3,"Belum Mencapai","Tidak Mencapai")) -> Tidak Mencapai
A26: 15 | B26: ='Audit Mandiri_IAU LAMKES'!C84 -> Bagaimana monitoring dan evaluasi kinerja tendik untuk meningkatkan kualitas layanan? | E26: ='Audit Mandiri_IAU LAMKES'!I84 -> 0 | G26: ='Audit Mandiri_IAU LAMKES'!H84 -> 0 | H26: =IF(G26=4,"Mencapai",IF(G26=3,"Belum Mencapai","Tidak Mencapai")) -> Tidak Mencapai
A27: 16 | B27: ='Audit Mandiri_IAU LAMKES'!C89 -> Bagaimana upaya UPPS/PS menjamin relevansi penelitian dosen dalam mendukung pencapaian visi misi dan unggulan program studi? | E27: ='Audit Mandiri_IAU LAMKES'!I89 -> 0 | G27: ='Audit Mandiri_IAU LAMKES'!H89 -> 0 | H27: =IF(G27=4,"Mencapai",IF(G27=3,"Belum Mencapai","Tidak Mencapai")) -> Tidak Mencapai
A28: 17 | B28: ='Audit Mandiri_IAU LAMKES'!C93 -> Bagaimana integrasi hasil penelitian dalam kegiatan pembelajaran? | E28: ='Audit Mandiri_IAU LAMKES'!I93 -> 0 | G28: ='Audit Mandiri_IAU LAMKES'!H93 -> 0 | H28: =IF(G28=4,"Mencapai",IF(G28=3,"Belum Mencapai","Tidak Mencapai")) -> Tidak Mencapai
A29: 18 | B29: ='Audit Mandiri_IAU LAMKES'!C98 -> Bagaimana upaya UPPS/PS menjamin relevansi Pengabdian Kepada Masyarakat (PkM) dosen dalam mendukung pencapaian visi misi dan unggulan Program Studi? | E29: ='Audit Mandiri_IAU LAMKES'!I98 -> 0 | G29: ='Audit Mandiri_IAU LAMKES'!H98 -> 0 | H29: =IF(G29=4,"Mencapai",IF(G29=3,"Belum Mencapai","Tidak Mencapai")) -> Tidak Mencapai
A30: 19 | B30: ='Audit Mandiri_IAU LAMKES'!C102 -> Bagaimana integrasi hasil PkM dalam kegiatan pembelajaran? | E30: ='Audit Mandiri_IAU LAMKES'!I102 -> 0 | G30: ='Audit Mandiri_IAU LAMKES'!H102 -> 0 | H30: =IF(G30=4,"Mencapai",IF(G30=3,"Belum Mencapai","Tidak Mencapai")) -> Tidak Mencapai
A31: 20 | B31: ='Audit Mandiri_IAU LAMKES'!C110 -> Bagaimana UPPS mengelola sumber dan/atau jumlah keuangan yang dapat berubah dari waktu ke waktu | E31: ='Audit Mandiri_IAU LAMKES'!I110 -> 0 | G31: ='Audit Mandiri_IAU LAMKES'!H110 -> 0 | H31: =IF(G31=4,"Mencapai",IF(G31=3,"Belum Mencapai","Tidak Mencapai")) -> Tidak Mencapai
A32: 21 | B32: ='Audit Mandiri_IAU LAMKES'!C113 -> Bagaimana UPPS menentukan kecukupan infrastruktur fisik (sarana dan prasarana) yang disediakan untuk pembelajaran teori dan praktik yang ditentukan dalam kurikulum? | E32: ='Audit Mandiri_IAU LAMKES'!I113 -> 0 | G32: ='Audit Mandiri_IAU LAMKES'!H113 -> 0 | H32: =IF(G32=4,"Mencapai",IF(G32=3,"Belum Mencapai","Tidak Mencapai")) -> Tidak Mencapai
A33: 22 | B33: ='Audit Mandiri_IAU LAMKES'!C121 -> Bagaimana pelaksanaan sistem penjaminan mutu internal di UPPS dan PS, dan sosialisasinya pada pemangku kepentingan internal dan eksternal? | E33: ='Audit Mandiri_IAU LAMKES'!I121 -> 0 | G33: ='Audit Mandiri_IAU LAMKES'!H121 -> 0 | H33: =IF(G33=4,"Mencapai",IF(G33=3,"Belum Mencapai","Tidak Mencapai")) -> Tidak Mencapai
A34: 23 | B34: ='Audit Mandiri_IAU LAMKES'!C125 -> Bagaimana sistem penjaminan mutu digunakan untuk meningkatkan mutu tridharma perguruan tinggi? | E34: ='Audit Mandiri_IAU LAMKES'!I125 -> 0 | G34: ='Audit Mandiri_IAU LAMKES'!H125 -> 0 | H34: =IF(G34=4,"Mencapai",IF(G34=3,"Belum Mencapai","Tidak Mencapai")) -> Tidak Mencapai
A35: 24 | B35: ='Audit Mandiri_IAU LAMKES'!C132 -> Bagaimana proses dan unit yang mendukung penyelenggaraan tridharma diatur di UPPS? | E35: ='Audit Mandiri_IAU LAMKES'!I132 -> 0 | G35: ='Audit Mandiri_IAU LAMKES'!H132 -> 0 | H35: =IF(G35=4,"Mencapai",IF(G35=3,"Belum Mencapai","Tidak Mencapai")) -> Tidak Mencapai
A36: 25 | B36: ='Audit Mandiri_IAU LAMKES'!C136 -> Bagaimana cara mengidentifikasi dan memitigasi risiko di UPPS? | E36: ='Audit Mandiri_IAU LAMKES'!I136 -> 0 | G36: ='Audit Mandiri_IAU LAMKES'!H136 -> 0 | H36: =IF(G36=4,"Mencapai",IF(G36=3,"Belum Mencapai","Tidak Mencapai")) -> Tidak Mencapai
A37: 26 | B37: ='Audit Mandiri_IAU LAMKES'!C139 -> Bagaimana UPPS menetapkan kebijakan tentang perwakilan mahasiswa dan partisipasi yang sesuai dalam proses akademik dan non akademik? | E37: ='Audit Mandiri_IAU LAMKES'!I139 -> 0 | G37: ='Audit Mandiri_IAU LAMKES'!H139 -> 0 | H37: =IF(G37=4,"Mencapai",IF(G37=3,"Belum Mencapai","Tidak Mencapai")) -> Tidak Mencapai
A38: 27 | H38: =IF(G38=4,"Mencapai",IF(G38=3,"Belum Mencapai","Tidak Mencapai")) -> Tidak Mencapai
A40: Siklus AMI | C40: Tgl Berlaku | E40: Status Audit
E41: Konfirmasi tindak lanjut Prodi atas hasil AMI siklus 3 sesuai format template yang disediakan beserta bukti pendukung
A42: Keterangan
A43: Permintaan Tindakan Koreksi (PTK) 1
...

Sheet Audit Mandiri_IAU Opto
I1: Form 2
B2: EVALUASI PROGRAM STUDI DIPLOMA TIGA
B3: YANG DI ISI HANYA SEL YANG BERWARNA KUNING
B4: Program Studi
B5: Bagian 1. Visi, Misi, Tujuan, Strategi
B6: NO. | C6: BAGIAN | H6: NILAI | I6: DESKRIPSI HASIL ASESMEN
B7: 1. | C7: Pemenuhan Unsur VMTS
B8: A. | C8: Bagaimana mekanisme penyusunan visi, misi, dan unggulan program studi dan alasannya?
C9: 4 | F9: 1. Prodi memiliki mekanisme untuk mengidentifikasi keterlibatan pemangku kepentingan internal dan eksternal dalam penyusunan visi, misi, dan unggulan; 2. Terdapat kontribusi dari pemangku kepentingan tersebut dan manfaat yang mereka dapatkan 3. Permasalahan kesehatan di tingkat nasional dan lokal dipertimbangkan dalam penyusunan visi, misi, dan unggulan
C10: 3 | F10: 1. Prodi memiliki mekanisme untuk mengidentifikasi keterlibatan pemangku kepentingan internal dan eksternal dalam penyusunan visi, misi, dan unggulan; 2. Terdapat kontribusi dari pemangku kepentingan tersebut dan manfaat yang mereka dapatkan.
C11: 0 | F11: -
B12: B. | C12: Bagaimana visi, misi, tujuan, strategi dan unggulan disesuaikan dengan rencana strategis, penjaminan mutu, dan manajemen di program studi?
C13: 4 | F13: • Program studi menerjemahkan visi, misi, tujuan, strategi dan unggulan ke dalam program dan aktivitas. • Program studi melakukan monitoring dan evaluasi terhadap pencapaian visi, misi, tujuan, strategi dan unggulan serta menindaklanjuti hasilnya guna perbaikan dan peningkatan.
C14: 3 | F14: • Program studi menerjemahkan visi, misi, tujuan, strategi dan unggulan ke dalam program dan aktivitas. • Program studi melakukan monitoring dan evaluasi terhadap pencapaian visi, misi, tujuan, strategi dan unggulan namun tidak ada dokumentasi tindaklanjut.
C15: 0 | F15: -
B16: C. | C16: Bagaimana cara menyosialisasikan visi, misi, dan unggulan program studi, analisis hasil dan tindaklanjutnya?
C17: 4 | F17: • Program studi menyosialisasikan visi, misi, tujuan, strategi dan unggulan dengan memanfaatkan berbagai media serta melibatkan pihak terkait. • Tersedia analisis hasil sosialisasi dan tindaklanjutnya.
C18: 3 | F18: • Program studi menyosialisasikan visi, misi, tujuan, strategi dan unggulan dengan memanfaatkan berbagai media serta melibatkan pihak terkait. • Tersedia analisis hasil sosialisasi namun tidak ada dokumentasi tindaklanjutnya.
C19: 0 | F19: -
B21: Bagian 2. Kurikulum
B22: NO. | C22: BAGIAN | H22: NILAI | I22: DESKRIPSI HASIL ASESMEN
B23: 2 | C23: Pemenuhan Unsur Kurikulum
B24: A. | C24: Bagaimana cara merancang dan mengembangkan capaian pembelajaran dan profil lulusan secara umum dan spesifik?
C25: 4 | F25: • Program studi merujuk pada visi, misi dan unggulan serta masalah kesehatan utama di masyarakat dalam perumusan capaian pembelajaran lulusan. • Capaian pembelajaran mata kuliah diturunkan secara konsisten dari capaian pembelajaran lulusan.
C26: 3 | F26: • Program studi merujuk pada visi, misi dan unggulan serta masalah kesehatan utama di masyarakat dalam perumusan capaian pembelajaran lulusan. • Capaian pembelajaran mata kuliah diturunkan secara konsisten dari capaian pembelajaran lulusan.
C27: 0 | F27: -
B28: B. | C28: Pendekatan apa yang digunakan dalam menyusun kurikulum dan bagaimana kesesuaiannya terhadap visi, misi, dan unggulan?
C29: 4 | F29: • Program studi menggunakan pendekatan pendidikan dan praktik kerja lapangan dalam penyusunan dan pengembangan kurikulum. • Penyusunan kurikulum selaras dengan visi, misi, dan unggulan program studi.
C30: 3 | F30: • Penyusunan kurikulum selaras dengan visi, misi, dan unggulan program studi.
C31: 0
B32: C. | C32: Bagaimana program studi menyediakan pengalaman belajar yang diperlukan mahasiswa untuk mencapai capaian pembelajaran?
C33: 4 | F33: • Program studi menyediakan pengalaman belajar variatif yang diperlukan oleh mahasiswa untuk mencapai capaian pembelajaran di fasilitas kesehatan dan institusi lainnya. • Kesesuaian tugas akhir dengan KKNI level 5 untuk Progam Studi Optometri Program Diploma Tiga.
C34: 3 | F34: • Program studi menyediakan pengalaman belajar variatif yang diperlukan oleh mahasiswa untuk mencapai capaian pembelajaran di fasilitas kesehatan dan institusi lainnya.
C35: 0 | F35: -
B36: D. | C36: Bagaimana memastikan capaian pembelajaran yang dipilih sesuai dengan konteks sosial dari wilayah program studi?
C37: 4 | F37: • Program studi memilih metode analisis kebutuhan yang sesuai dengan sumber daya yang tersedia. • Capaian pembelajaran lulusan dikaitkan dengan prioritas masalah kesehatan di wilayahnya.
C38: 3 | F38: • Program studi memilih metode analisis kebutuhan yang sesuai dengan sumber daya yang tersedia.
C39: 0 | F39: -
B40: E. | C40: Elemen apa saja dari bidang teknologi Optometri, dan kesehatan lainnya yang dimasukkan dalam kurikulum? Bagaimana pilihan yang dibuat dan waktu yang dialokasikan untuk elemen tersebut?
C41: 4 | F41: • Program studi mengidentifikasi bidang teknologi Optometri, dan kesehatan lainnya yang relevan dengan capaian pembelajaran lulusan. • Program studi menentukan isi kurikulum bidang teknologi Optometri, kolaborasi antar profesi kesehatan dan kesehatan lainnya, alokasi waktu, dan nilai satuan kredit.
...

Sheet Form 3 Opt
I1: Form 3
C2: Berita Acara Audit Mutu Internal
H3: Periode Audit:
H4: TA 2025/2026
C5: Teraudit: | D5: Program Studi | F5: ='Audit Mandiri_IAU Opto'!G4 -> 0 | H5: Tanggal Audit
C6: Ruang Lingkup: | E6: Akademik/Non Akademik
A8: Hasil Konfirmasi Auditee
A9: Penyelesaian Permintaan Tindakan Koreksi (PTK) AMI siklus sebelumnya
A10: No | B10: Pernyataan Standar | E10: Konfirmasi Auditee | G10: Skor | H10: Status Akhir
A12: 1 | B12: ='Audit Mandiri_IAU Opto'!C8 -> Bagaimana mekanisme penyusunan visi, misi, dan unggulan program studi dan alasannya? | E12: ='Audit Mandiri_IAU Opto'!I8 -> 0 | G12: ='Audit Mandiri_IAU Opto'!H8 -> 0 | H12: =IF(G12=4,"Mencapai",IF(G12=3,"Belum Mencapai","Tidak Mencapai")) -> Tidak Mencapai
A13: 2 | B13: ='Audit Mandiri_IAU Opto'!C12 -> Bagaimana visi, misi, tujuan, strategi dan unggulan disesuaikan dengan rencana strategis, penjaminan mutu, dan manajemen di program studi? | E13: ='Audit Mandiri_IAU Opto'!I12 -> 0 | G13: ='Audit Mandiri_IAU Opto'!H12 -> 0 | H13: =IF(G13=4,"Mencapai",IF(G13=3,"Belum Mencapai","Tidak Mencapai")) -> Tidak Mencapai
A14: 3 | B14: ='Audit Mandiri_IAU Opto'!C16 -> Bagaimana cara menyosialisasikan visi, misi, dan unggulan program studi, analisis hasil dan tindaklanjutnya? | E14: ='Audit Mandiri_IAU Opto'!I16 -> 0 | G14: ='Audit Mandiri_IAU Opto'!H16 -> 0 | H14: =IF(G14=4,"Mencapai",IF(G14=3,"Belum Mencapai","Tidak Mencapai")) -> Tidak Mencapai
A15: 4 | B15: ='Audit Mandiri_IAU Opto'!C24 -> Bagaimana cara merancang dan mengembangkan capaian pembelajaran dan profil lulusan secara umum dan spesifik? | E15: ='Audit Mandiri_IAU Opto'!I24 -> 0 | G15: ='Audit Mandiri_IAU Opto'!H24 -> 0 | H15: =IF(G15=4,"Mencapai",IF(G15=3,"Belum Mencapai","Tidak Mencapai")) -> Tidak Mencapai
A16: 5 | B16: ='Audit Mandiri_IAU Opto'!C28 -> Pendekatan apa yang digunakan dalam menyusun kurikulum dan bagaimana kesesuaiannya terhadap visi, misi, dan unggulan? | E16: ='Audit Mandiri_IAU Opto'!I28 -> 0 | G16: ='Audit Mandiri_IAU Opto'!H28 -> 0 | H16: =IF(G16=4,"Mencapai",IF(G16=3,"Belum Mencapai","Tidak Mencapai")) -> Tidak Mencapai
A17: 6 | B17: ='Audit Mandiri_IAU Opto'!C32 -> Bagaimana program studi menyediakan pengalaman belajar yang diperlukan mahasiswa untuk mencapai capaian pembelajaran? | E17: ='Audit Mandiri_IAU Opto'!I32 -> 0 | G17: ='Audit Mandiri_IAU Opto'!H32 -> 0 | H17: =IF(G17=4,"Mencapai",IF(G17=3,"Belum Mencapai","Tidak Mencapai")) -> Tidak Mencapai
A18: 7 | B18: ='Audit Mandiri_IAU Opto'!C36 -> Bagaimana memastikan capaian pembelajaran yang dipilih sesuai dengan konteks sosial dari wilayah program studi? | E18: ='Audit Mandiri_IAU Opto'!I36 -> 0 | G18: ='Audit Mandiri_IAU Opto'!H36 -> 0 | H18: =IF(G18=4,"Mencapai",IF(G18=3,"Belum Mencapai","Tidak Mencapai")) -> Tidak Mencapai
A19: 8 | B19: ='Audit Mandiri_IAU Opto'!C40 -> Elemen apa saja dari bidang teknologi Optometri, dan kesehatan lainnya yang dimasukkan dalam kurikulum? Bagaimana pilihan yang dibuat dan waktu yang dialokasikan untuk elemen tersebut? | E19: ='Audit Mandiri_IAU Opto'!I40 -> 0 | G19: ='Audit Mandiri_IAU Opto'!H40 -> 0 | H19: =IF(G19=4,"Mencapai",IF(G19=3,"Belum Mencapai","Tidak Mencapai")) -> Tidak Mencapai
A20: 9 | B20: ='Audit Mandiri_IAU Opto'!C44 -> Bagaimana PS menetapkan kelompok atau individu yang bertanggung jawab untuk memantau kesalahan mahasiswa dan keselamatan pasien di tingkat manajemen program vokasi dan layanan kesehatan? | E20: ='Audit Mandiri_IAU Opto'!I44 -> 0 | G20: ='Audit Mandiri_IAU Opto'!H44 -> 0 | H20: =IF(G20=4,"Mencapai",IF(G20=3,"Belum Mencapai","Tidak Mencapai")) -> Tidak Mencapai
A21: 10 | B21: ='Audit Mandiri_IAU Opto'!C52 -> Bagaimana penilaian diintegrasikan dan dikoordinasikan pada berbagai capaian pembelajaran dan kurikulum? | E21: ='Audit Mandiri_IAU Opto'!I52 -> 0 | G21: ='Audit Mandiri_IAU Opto'!H52 -> 0 | H21: =IF(G21=4,"Mencapai",IF(G21=3,"Belum Mencapai","Tidak Mencapai")) -> Tidak Mencapai
A22: 11 | B22: ='Audit Mandiri_IAU Opto'!C56 -> Bagaimana standar (nilai kelulusan) ditetapkan pada ujian sumatif? | E22: ='Audit Mandiri_IAU Opto'!I56 -> 0 | G22: ='Audit Mandiri_IAU Opto'!H56 -> 0 | H22: =IF(G22=4,"Mencapai",IF(G22=3,"Belum Mencapai","Tidak Mencapai")) -> Tidak Mencapai
A23: 12 | B23: ='Audit Mandiri_IAU Opto'!C60 -> Bagaimana setiap penilaian dianalisis untuk memastikan kualitasnya? | E23: ='Audit Mandiri_IAU Opto'!I60 -> 0 | G23: ='Audit Mandiri_IAU Opto'!H60 -> 0 | H23: =IF(G23=4,"Mencapai",IF(G23=3,"Belum Mencapai","Tidak Mencapai")) -> Tidak Mencapai
A24: 13 | B24: ='Audit Mandiri_IAU Opto'!C68 -> Bagaimana kebijakan seleksi penerimaan maba disosialisasikan,dikaji dan direvisi secara berkala? | E24: ='Audit Mandiri_IAU Opto'!I68 -> 0 | G24: ='Audit Mandiri_IAU Opto'!H68 -> 0 | H24: =IF(G24=4,"Mencapai",IF(G24=3,"Belum Mencapai","Tidak Mencapai")) -> Tidak Mencapai
A25: 14 | B25: ='Audit Mandiri_IAU Opto'!C72 -> Bagaimana layanan dikaji secara berkala bersama perwakilan mahasiswa untuk memastikan relevansi, aksesibilitas, dan kerahasiaan? | E25: ='Audit Mandiri_IAU Opto'!I72 -> 0 | G25: ='Audit Mandiri_IAU Opto'!H72 -> 0 | H25: =IF(G25=4,"Mencapai",IF(G25=3,"Belum Mencapai","Tidak Mencapai")) -> Tidak Mencapai
A26: 15 | B26: ='Audit Mandiri_IAU Opto'!C76 -> Bagaimana PS mengatur pelaksanaan dan tanggung jawab praktik lapangan bagi mahasiswa? | E26: ='Audit Mandiri_IAU Opto'!I76 -> 0 | G26: ='Audit Mandiri_IAU Opto'!H76 -> 0 | H26: =IF(G26=4,"Mencapai",IF(G26=3,"Belum Mencapai","Tidak Mencapai")) -> Tidak Mencapai
A27: 16 | B27: ='Audit Mandiri_IAU Opto'!C80 -> Bagaimana UPPS/Prodi mencegah risiko yang membahayakan keselamatan mahasiswa? | E27: ='Audit Mandiri_IAU Opto'!I80 -> 0 | G27: ='Audit Mandiri_IAU Opto'!H80 -> 0 | H27: =IF(G27=4,"Mencapai",IF(G27=3,"Belum Mencapai","Tidak Mencapai")) -> Tidak Mencapai
A28: 17 | B28: ='Audit Mandiri_IAU Opto'!C88 -> Bagaimana PS menetapkan jumlah dan kualifikasi dosen agar selaras dengan rancangan, penerapan, dan penjaminan mutu kurikulum? | E28: ='Audit Mandiri_IAU Opto'!I88 -> 0 | G28: ='Audit Mandiri_IAU Opto'!H88 -> 0 | H28: =IF(G28=4,"Mencapai",IF(G28=3,"Belum Mencapai","Tidak Mencapai")) -> Tidak Mencapai
A29: 18 | B29: ='Audit Mandiri_IAU Opto'!C92 -> Bagaimana PS menyiapkan dosen akademik dan pembimbing lapangan untuk melaksanakan kurikulum yang telah disusun? | E29: ='Audit Mandiri_IAU Opto'!I92 -> 0 | G29: ='Audit Mandiri_IAU Opto'!H92 -> 0 | H29: =IF(G29=4,"Mencapai",IF(G29=3,"Belum Mencapai","Tidak Mencapai")) -> Tidak Mencapai
A30: 19 | B30: ='Audit Mandiri_IAU Opto'!C96 -> Bagaimana monitoring dan evaluasi kinerja tendik untuk meningkatkan kualitas layanan? | E30: ='Audit Mandiri_IAU Opto'!I96 -> 0 | G30: ='Audit Mandiri_IAU Opto'!H96 -> 0 | H30: =IF(G30=4,"Mencapai",IF(G30=3,"Belum Mencapai","Tidak Mencapai")) -> Tidak Mencapai
A31: 20 | B31: ='Audit Mandiri_IAU Opto'!C101 -> Bagaimana program studi menjamin relevansi penelitian dosen dalam mendukung pencapaian visi misi dan unggulan program studi serta monitoring, evaluasi dan tindaklanjutnya? | E31: ='Audit Mandiri_IAU Opto'!I101 -> 0 | G31: ='Audit Mandiri_IAU Opto'!H101 -> 0 | H31: =IF(G31=4,"Mencapai",IF(G31=3,"Belum Mencapai","Tidak Mencapai")) -> Tidak Mencapai
A32: 21 | B32: ='Audit Mandiri_IAU Opto'!C105 -> Bagaimana integrasi hasil penelitian dalam kegiatan pembelajaran? | E32: ='Audit Mandiri_IAU Opto'!I105 -> 0 | G32: ='Audit Mandiri_IAU Opto'!H105 -> 0 | H32: =IF(G32=4,"Mencapai",IF(G32=3,"Belum Mencapai","Tidak Mencapai")) -> Tidak Mencapai
A33: 22 | B33: ='Audit Mandiri_IAU Opto'!C110 -> Bagaimana upaya Program studi menjamin relevansi Pengabdian Kepada Masyarakat (PkM) dosen dalam mendukung pencapaian visi misi dan keunggulan Program studi serta monitoring, evaluasi dan tindak lanjutnya? | E33: ='Audit Mandiri_IAU Opto'!I110 -> 0 | G33: ='Audit Mandiri_IAU Opto'!H110 -> 0 | H33: =IF(G33=4,"Mencapai",IF(G33=3,"Belum Mencapai","Tidak Mencapai")) -> Tidak Mencapai
A34: 23 | B34: ='Audit Mandiri_IAU Opto'!C114 -> Bagaimana integrasi hasil PkM dalam kegiatan pembelajaran? | E34: ='Audit Mandiri_IAU Opto'!I114 -> 0 | G34: ='Audit Mandiri_IAU Opto'!H114 -> 0 | H34: =IF(G34=4,"Mencapai",IF(G34=3,"Belum Mencapai","Tidak Mencapai")) -> Tidak Mencapai
A35: 24 | B35: ='Audit Mandiri_IAU Opto'!C122 -> Bagaimana UPPS menentukan kecukupan infrastruktur fisik (sarana dan prasarana) yang disediakan untuk pembelajaran teori dan praktik yang ditentukan dalam kurikulum? | E35: ='Audit Mandiri_IAU Opto'!I122 -> 0 | G35: ='Audit Mandiri_IAU Opto'!H122 -> 0 | H35: =IF(G35=4,"Mencapai",IF(G35=3,"Belum Mencapai","Tidak Mencapai")) -> Tidak Mencapai
A36: 25 | B36: ='Audit Mandiri_IAU Opto'!C126 -> Bagaimana penggunaan skill’s lab (laboratorium keterampilan), pasien simulasi, dan pasien sebenarnya dalam memperoleh keterampilan klinik mahasiwa? | E36: ='Audit Mandiri_IAU Opto'!I126 -> 0 | G36: ='Audit Mandiri_IAU Opto'!H126 -> 0 | H36: =IF(G36=4,"Mencapai",IF(G36=3,"Belum Mencapai","Tidak Mencapai")) -> Tidak Mencapai
A37: 26 | B37: ='Audit Mandiri_IAU Opto'!C138 -> Bagaimana sistem penjaminan mutu internal dilaksanakan di UPPS dan PS dan disosialisasikan? | E37: ='Audit Mandiri_IAU Opto'!I138 -> 0 | G37: ='Audit Mandiri_IAU Opto'!H138 -> 0 | H37: =IF(G37=4,"Mencapai",IF(G37=3,"Belum Mencapai","Tidak Mencapai")) -> Tidak Mencapai
A38: 27 | B38: ='Audit Mandiri_IAU Opto'!C142 -> Bagaimana sistem penjaminan mutu digunakan untuk meningkatkan mutu tridharma perguruan tinggi? | E38: ='Audit Mandiri_IAU Opto'!I142 -> 0 | G38: ='Audit Mandiri_IAU Opto'!H142 -> 0 | H38: =IF(G38=4,"Mencapai",IF(G38=3,"Belum Mencapai","Tidak Mencapai")) -> Tidak Mencapai
A39: 28 | B39: ='Audit Mandiri_IAU Opto'!C150 -> Bagaimana cara UPPS mengidentifikasi dan memitigasi risiko? | E39: ='Audit Mandiri_IAU Opto'!I150 -> 0 | G39: ='Audit Mandiri_IAU Opto'!H150 -> 0 | H39: =IF(G39=4,"Mencapai",IF(G39=3,"Belum Mencapai","Tidak Mencapai")) -> Tidak Mencapai
A40: 29 | B40: ='Audit Mandiri_IAU Opto'!C154 -> Bagaimana cara mengidentifikasi dan memitigasi risiko di UPPS? | E40: ='Audit Mandiri_IAU Opto'!I154 -> 0 | G40: ='Audit Mandiri_IAU Opto'!H154 -> 0 | H40: =IF(G40=4,"Mencapai",IF(G40=3,"Belum Mencapai","Tidak Mencapai")) -> Tidak Mencapai
A41: 30 | B41: ='Audit Mandiri_IAU Opto'!C157 -> Bagaimana UPPS menetapkan kebijakan tentang perwakilan mahasiswa dan partisipasi yang sesuai dalam proses akademik dan non akademik? | E41: ='Audit Mandiri_IAU Opto'!I157 -> 0 | G41: ='Audit Mandiri_IAU Opto'!H157 -> 0 | H41: =IF(G41=4,"Mencapai",IF(G41=3,"Belum Mencapai","Tidak Mencapai")) -> Tidak Mencapai
A42: 31 | B42: ='Audit Mandiri_IAU Opto'!C38 -> 3 | H42: =IF(G42=4,"Mencapai",IF(G42=3,"Belum Mencapai","Tidak Mencapai")) -> Tidak Mencapai
...
